{
  "affected_release": null,
  "package_state": [
    {
      "product_name": "Red Hat Enterprise Linux 6",
      "fix_state": "Not affected",
      "package_name": "kernel",
      "cpe": "cpe:/o:redhat:enterprise_linux:6"
    },
    {
      "product_name": "Red Hat Enterprise Linux 7",
      "fix_state": "Out of support scope",
      "package_name": "kernel",
      "cpe": "cpe:/o:redhat:enterprise_linux:7"
    },
    {
      "product_name": "Red Hat Enterprise Linux 7",
      "fix_state": "Out of support scope",
      "package_name": "kernel-rt",
      "cpe": "cpe:/o:redhat:enterprise_linux:7"
    },
    {
      "product_name": "Red Hat Enterprise Linux 8",
      "fix_state": "Not affected",
      "package_name": "kernel",
      "cpe": "cpe:/o:redhat:enterprise_linux:8"
    },
    {
      "product_name": "Red Hat Enterprise Linux 8",
      "fix_state": "Not affected",
      "package_name": "kernel-rt",
      "cpe": "cpe:/o:redhat:enterprise_linux:8"
    },
    {
      "product_name": "Red Hat Enterprise Linux 9",
      "fix_state": "Not affected",
      "package_name": "kernel",
      "cpe": "cpe:/o:redhat:enterprise_linux:9"
    },
    {
      "product_name": "Red Hat Enterprise Linux 9",
      "fix_state": "Not affected",
      "package_name": "kernel-rt",
      "cpe": "cpe:/o:redhat:enterprise_linux:9"
    }
  ],
  "threat_severity": "Low",
  "public_date": "2025-05-08T00:00:00Z",
  "bugzilla": {
    "description": "kernel: nvmet: fix out-of-bounds access in nvmet_enable_port",
    "id": "2365011",
    "url": "https://bugzilla.redhat.com/show_bug.cgi?id=2365011"
  },
  "cvss": {
    "cvss_base_score": "",
    "cvss_scoring_vector": "",
    "status": ""
  },
  "cvss3": {
    "cvss3_base_score": "5.5",
    "cvss3_scoring_vector": "CVSS:3.1/AV:L/AC:L/PR:L/UI:N/S:U/C:N/I:N/A:H",
    "status": "draft"
  },
  "iava": "",
  "cwe": "",
  "statement": "",
  "acknowledgement": "",
  "name": "CVE-2025-37825",
  "document_distribution": "",
  "details": [
    "In the Linux kernel, the following vulnerability has been resolved:\nnvmet: fix out-of-bounds access in nvmet_enable_port\nWhen trying to enable a port that has no transport configured yet,\nnvmet_enable_port() uses NVMF_TRTYPE_MAX (255) to query the transports\narray, causing an out-of-bounds access:\n[  106.058694] BUG: KASAN: global-out-of-bounds in nvmet_enable_port+0x42/0x1da\n[  106.058719] Read of size 8 at addr ffffffff89dafa58 by task ln/632\n[...]\n[  106.076026] nvmet: transport type 255 not supported\nSince commit 200adac75888, NVMF_TRTYPE_MAX is the default state as configured by\nnvmet_ports_make().\nAvoid this by checking for NVMF_TRTYPE_MAX before proceeding."
  ],
  "references": [
    "https://www.cve.org/CVERecord?id=CVE-2025-37825\nhttps://nvd.nist.gov/vuln/detail/CVE-2025-37825\nhttps://lore.kernel.org/linux-cve-announce/2025050822-CVE-2025-37825-547b@gregkh/T"
  ]
}