{
  "affected_release": null,
  "package_state": [
    {
      "product_name": "Red Hat Enterprise Linux 6",
      "fix_state": "Out of support scope",
      "package_name": "kernel",
      "cpe": "cpe:/o:redhat:enterprise_linux:6"
    },
    {
      "product_name": "Red Hat Enterprise Linux 7",
      "fix_state": "Out of support scope",
      "package_name": "kernel",
      "cpe": "cpe:/o:redhat:enterprise_linux:7"
    },
    {
      "product_name": "Red Hat Enterprise Linux 7",
      "fix_state": "Out of support scope",
      "package_name": "kernel-rt",
      "cpe": "cpe:/o:redhat:enterprise_linux:7"
    },
    {
      "product_name": "Red Hat Enterprise Linux 8",
      "fix_state": "Not affected",
      "package_name": "kernel",
      "cpe": "cpe:/o:redhat:enterprise_linux:8"
    },
    {
      "product_name": "Red Hat Enterprise Linux 8",
      "fix_state": "Not affected",
      "package_name": "kernel-rt",
      "cpe": "cpe:/o:redhat:enterprise_linux:8"
    },
    {
      "product_name": "Red Hat Enterprise Linux 9",
      "fix_state": "Not affected",
      "package_name": "kernel",
      "cpe": "cpe:/o:redhat:enterprise_linux:9"
    },
    {
      "product_name": "Red Hat Enterprise Linux 9",
      "fix_state": "Not affected",
      "package_name": "kernel-rt",
      "cpe": "cpe:/o:redhat:enterprise_linux:9"
    }
  ],
  "threat_severity": "Low",
  "public_date": "2025-04-16T00:00:00Z",
  "bugzilla": {
    "description": "kernel: ext4: goto right label 'out_mmap_sem' in ext4_setattr()",
    "id": "2360213",
    "url": "https://bugzilla.redhat.com/show_bug.cgi?id=2360213"
  },
  "cvss": {
    "cvss_base_score": "",
    "cvss_scoring_vector": "",
    "status": ""
  },
  "cvss3": {
    "cvss3_base_score": "5.5",
    "cvss3_scoring_vector": "CVSS:3.1/AV:L/AC:L/PR:L/UI:N/S:U/C:N/I:N/A:H",
    "status": "draft"
  },
  "iava": "",
  "cwe": "",
  "statement": "",
  "acknowledgement": "",
  "name": "CVE-2025-22120",
  "document_distribution": "",
  "details": [
    "In the Linux kernel, the following vulnerability has been resolved:\next4: goto right label 'out_mmap_sem' in ext4_setattr()\nOtherwise, if ext4_inode_attach_jinode() fails, a hung task will\nhappen because filemap_invalidate_unlock() isn't called to unlock\nmapping-\u003einvalidate_lock. Like this:\nEXT4-fs error (device sda) in ext4_setattr:5557: Out of memory\nINFO: task fsstress:374 blocked for more than 122 seconds.\nNot tainted 6.14.0-rc1-next-20250206-xfstests-dirty #726\n\"echo 0 \u003e /proc/sys/kernel/hung_task_timeout_secs\" disables this message.\ntask:fsstress state:D stack:0     pid:374   tgid:374   ppid:373\ntask_flags:0x440140 flags:0x00000000\nCall Trace:\n\u003cTASK\u003e\n__schedule+0x2c9/0x7f0\nschedule+0x27/0xa0\nschedule_preempt_disabled+0x15/0x30\nrwsem_down_read_slowpath+0x278/0x4c0\ndown_read+0x59/0xb0\npage_cache_ra_unbounded+0x65/0x1b0\nfilemap_get_pages+0x124/0x3e0\nfilemap_read+0x114/0x3d0\nvfs_read+0x297/0x360\nksys_read+0x6c/0xe0\ndo_syscall_64+0x4b/0x110\nentry_SYSCALL_64_after_hwframe+0x76/0x7e"
  ],
  "references": [
    "https://www.cve.org/CVERecord?id=CVE-2025-22120\nhttps://nvd.nist.gov/vuln/detail/CVE-2025-22120\nhttps://lore.kernel.org/linux-cve-announce/2025041627-CVE-2025-22120-24ce@gregkh/T"
  ]
}