{
  "affected_release": null,
  "package_state": [
    {
      "product_name": "Red Hat Enterprise Linux 6",
      "fix_state": "Out of support scope",
      "package_name": "kernel",
      "cpe": "cpe:/o:redhat:enterprise_linux:6"
    },
    {
      "product_name": "Red Hat Enterprise Linux 7",
      "fix_state": "Out of support scope",
      "package_name": "kernel",
      "cpe": "cpe:/o:redhat:enterprise_linux:7"
    },
    {
      "product_name": "Red Hat Enterprise Linux 7",
      "fix_state": "Out of support scope",
      "package_name": "kernel-rt",
      "cpe": "cpe:/o:redhat:enterprise_linux:7"
    },
    {
      "product_name": "Red Hat Enterprise Linux 8",
      "fix_state": "Out of support scope",
      "package_name": "kernel",
      "cpe": "cpe:/o:redhat:enterprise_linux:8"
    },
    {
      "product_name": "Red Hat Enterprise Linux 8",
      "fix_state": "Out of support scope",
      "package_name": "kernel-rt",
      "cpe": "cpe:/o:redhat:enterprise_linux:8"
    },
    {
      "product_name": "Red Hat Enterprise Linux 9",
      "fix_state": "Fix deferred",
      "package_name": "kernel",
      "cpe": "cpe:/o:redhat:enterprise_linux:9"
    },
    {
      "product_name": "Red Hat Enterprise Linux 9",
      "fix_state": "Fix deferred",
      "package_name": "kernel-rt",
      "cpe": "cpe:/o:redhat:enterprise_linux:9"
    }
  ],
  "threat_severity": "Moderate",
  "public_date": "2025-05-01T00:00:00Z",
  "bugzilla": {
    "description": "kernel: ipvs: fix WARNING in ip_vs_app_net_cleanup()",
    "id": "2363476",
    "url": "https://bugzilla.redhat.com/show_bug.cgi?id=2363476"
  },
  "cvss": {
    "cvss_base_score": "",
    "cvss_scoring_vector": "",
    "status": ""
  },
  "cvss3": {
    "cvss3_base_score": "5.5",
    "cvss3_scoring_vector": "CVSS:3.1/AV:L/AC:L/PR:L/UI:N/S:U/C:N/I:N/A:H",
    "status": "draft"
  },
  "iava": "",
  "cwe": "",
  "statement": "",
  "acknowledgement": "",
  "name": "CVE-2022-49917",
  "document_distribution": "",
  "details": [
    "In the Linux kernel, the following vulnerability has been resolved:\nipvs: fix WARNING in ip_vs_app_net_cleanup()\nDuring the initialization of ip_vs_app_net_init(), if file ip_vs_app\nfails to be created, the initialization is successful by default.\nTherefore, the ip_vs_app file doesn't be found during the remove in\nip_vs_app_net_cleanup(). It will cause WRNING.\nThe following is the stack information:\nname 'ip_vs_app'\nWARNING: CPU: 1 PID: 9 at fs/proc/generic.c:712 remove_proc_entry+0x389/0x460\nModules linked in:\nWorkqueue: netns cleanup_net\nRIP: 0010:remove_proc_entry+0x389/0x460\nCall Trace:\n\u003cTASK\u003e\nops_exit_list+0x125/0x170\ncleanup_net+0x4ea/0xb00\nprocess_one_work+0x9bf/0x1710\nworker_thread+0x665/0x1080\nkthread+0x2e4/0x3a0\nret_from_fork+0x1f/0x30\n\u003c/TASK\u003e"
  ],
  "references": [
    "https://www.cve.org/CVERecord?id=CVE-2022-49917\nhttps://nvd.nist.gov/vuln/detail/CVE-2022-49917\nhttps://lore.kernel.org/linux-cve-announce/2025050107-CVE-2022-49917-50af@gregkh/T"
  ]
}